[2023-11-20T22:47:44.777+0000] {taskinstance.py:1159} INFO - Dependencies all met for dep_context=non-requeueable deps ti=<TaskInstance: austin_animal_shelter_dag.load_data manual__2023-11-20T22:47:29.986610+00:00 [queued]>
[2023-11-20T22:47:44.797+0000] {taskinstance.py:1159} INFO - Dependencies all met for dep_context=requeueable deps ti=<TaskInstance: austin_animal_shelter_dag.load_data manual__2023-11-20T22:47:29.986610+00:00 [queued]>
[2023-11-20T22:47:44.803+0000] {taskinstance.py:1361} INFO - Starting attempt 1 of 2
[2023-11-20T22:47:44.847+0000] {taskinstance.py:1382} INFO - Executing <Task(PythonOperator): load_data> on 2023-11-20 22:47:29.986610+00:00
[2023-11-20T22:47:44.865+0000] {standard_task_runner.py:57} INFO - Started process 144 to run task
[2023-11-20T22:47:44.866+0000] {standard_task_runner.py:84} INFO - Running: ['***', 'tasks', 'run', 'austin_animal_shelter_dag', 'load_data', 'manual__2023-11-20T22:47:29.986610+00:00', '--job-id', '29', '--raw', '--subdir', 'DAGS_FOLDER/DAG.py', '--cfg-path', '/tmp/tmp013_rlyl']
[2023-11-20T22:47:44.877+0000] {standard_task_runner.py:85} INFO - Job 29: Subtask load_data
[2023-11-20T22:47:44.968+0000] {task_command.py:416} INFO - Running <TaskInstance: austin_animal_shelter_dag.load_data manual__2023-11-20T22:47:29.986610+00:00 [running]> on host fda681cc78c9
[2023-11-20T22:47:45.111+0000] {taskinstance.py:1662} INFO - Exporting env vars: AIRFLOW_CTX_DAG_OWNER='***' AIRFLOW_CTX_DAG_ID='austin_animal_shelter_dag' AIRFLOW_CTX_TASK_ID='load_data' AIRFLOW_CTX_EXECUTION_DATE='2023-11-20T22:47:29.986610+00:00' AIRFLOW_CTX_TRY_NUMBER='1' AIRFLOW_CTX_DAG_RUN_ID='manual__2023-11-20T22:47:29.986610+00:00'
[2023-11-20T22:47:48.899+0000] {taskinstance.py:1937} ERROR - Task failed with exception
Traceback (most recent call last):
  File "/home/airflow/.local/lib/python3.8/site-packages/sqlalchemy/engine/base.py", line 1910, in _execute_context
    self.dialect.do_execute(
  File "/home/airflow/.local/lib/python3.8/site-packages/sqlalchemy/engine/default.py", line 736, in do_execute
    cursor.execute(statement, parameters)
psycopg2.errors.UniqueViolation: duplicate key value violates unique constraint "pg_type_typname_nsp_index"
DETAIL:  Key (typname, typnamespace)=(animal, 2200) already exists.


The above exception was the direct cause of the following exception:

Traceback (most recent call last):
  File "/home/airflow/.local/lib/python3.8/site-packages/airflow/operators/python.py", line 192, in execute
    return_value = self.execute_callable()
  File "/home/airflow/.local/lib/python3.8/site-packages/airflow/operators/python.py", line 209, in execute_callable
    return self.python_callable(*self.op_args, **self.op_kwargs)
  File "/opt/airflow/dags/Scripts/etl.py", line 209, in load_data
    dataframes['cleaned_data/animal.csv'].to_sql('animal', engine, if_exists='append', index=False)
  File "/home/airflow/.local/lib/python3.8/site-packages/pandas/core/generic.py", line 2878, in to_sql
    return sql.to_sql(
  File "/home/airflow/.local/lib/python3.8/site-packages/pandas/io/sql.py", line 769, in to_sql
    return pandas_sql.to_sql(
  File "/home/airflow/.local/lib/python3.8/site-packages/pandas/io/sql.py", line 1910, in to_sql
    table = self.prep_table(
  File "/home/airflow/.local/lib/python3.8/site-packages/pandas/io/sql.py", line 1814, in prep_table
    table.create()
  File "/home/airflow/.local/lib/python3.8/site-packages/pandas/io/sql.py", line 914, in create
    self._execute_create()
  File "/home/airflow/.local/lib/python3.8/site-packages/pandas/io/sql.py", line 900, in _execute_create
    self.table.create(bind=self.pd_sql.con)
  File "/home/airflow/.local/lib/python3.8/site-packages/sqlalchemy/sql/schema.py", line 962, in create
    bind._run_ddl_visitor(ddl.SchemaGenerator, self, checkfirst=checkfirst)
  File "/home/airflow/.local/lib/python3.8/site-packages/sqlalchemy/engine/base.py", line 2221, in _run_ddl_visitor
    visitorcallable(self.dialect, self, **kwargs).traverse_single(element)
  File "/home/airflow/.local/lib/python3.8/site-packages/sqlalchemy/sql/visitors.py", line 524, in traverse_single
    return meth(obj, **kw)
  File "/home/airflow/.local/lib/python3.8/site-packages/sqlalchemy/sql/ddl.py", line 899, in visit_table
    self.connection.execute(
  File "/home/airflow/.local/lib/python3.8/site-packages/sqlalchemy/engine/base.py", line 1385, in execute
    return meth(self, multiparams, params, _EMPTY_EXECUTION_OPTS)
  File "/home/airflow/.local/lib/python3.8/site-packages/sqlalchemy/sql/ddl.py", line 80, in _execute_on_connection
    return connection._execute_ddl(
  File "/home/airflow/.local/lib/python3.8/site-packages/sqlalchemy/engine/base.py", line 1477, in _execute_ddl
    ret = self._execute_context(
  File "/home/airflow/.local/lib/python3.8/site-packages/sqlalchemy/engine/base.py", line 1953, in _execute_context
    self._handle_dbapi_exception(
  File "/home/airflow/.local/lib/python3.8/site-packages/sqlalchemy/engine/base.py", line 2134, in _handle_dbapi_exception
    util.raise_(
  File "/home/airflow/.local/lib/python3.8/site-packages/sqlalchemy/util/compat.py", line 211, in raise_
    raise exception
  File "/home/airflow/.local/lib/python3.8/site-packages/sqlalchemy/engine/base.py", line 1910, in _execute_context
    self.dialect.do_execute(
  File "/home/airflow/.local/lib/python3.8/site-packages/sqlalchemy/engine/default.py", line 736, in do_execute
    cursor.execute(statement, parameters)
sqlalchemy.exc.IntegrityError: (psycopg2.errors.UniqueViolation) duplicate key value violates unique constraint "pg_type_typname_nsp_index"
DETAIL:  Key (typname, typnamespace)=(animal, 2200) already exists.

[SQL: 
CREATE TABLE animal (
	animal_id TEXT, 
	breed TEXT, 
	color TEXT, 
	name TEXT, 
	date_of_birth TEXT, 
	animal_type TEXT
)

]
(Background on this error at: https://sqlalche.me/e/14/gkpj)
[2023-11-20T22:47:48.962+0000] {taskinstance.py:1400} INFO - Marking task as UP_FOR_RETRY. dag_id=austin_animal_shelter_dag, task_id=load_data, execution_date=20231120T224729, start_date=20231120T224744, end_date=20231120T224748
[2023-11-20T22:47:49.071+0000] {standard_task_runner.py:104} ERROR - Failed to execute job 29 for task load_data ((psycopg2.errors.UniqueViolation) duplicate key value violates unique constraint "pg_type_typname_nsp_index"
DETAIL:  Key (typname, typnamespace)=(animal, 2200) already exists.

[SQL: 
CREATE TABLE animal (
	animal_id TEXT, 
	breed TEXT, 
	color TEXT, 
	name TEXT, 
	date_of_birth TEXT, 
	animal_type TEXT
)

]
(Background on this error at: https://sqlalche.me/e/14/gkpj); 144)
[2023-11-20T22:47:49.105+0000] {local_task_job_runner.py:228} INFO - Task exited with return code 1
[2023-11-20T22:47:49.175+0000] {taskinstance.py:2778} INFO - 0 downstream tasks scheduled from follow-on schedule check
